2024-10-29 14:35:49,865 ERROR frappe Could not take error snapshot: 'NoneType' object has no attribute 'get'
Site: test.localhost
Form Dict: {}
Traceback (most recent call last):
  File "/mnt/frappe-axe/apps/frappe/frappe/app.py", line 99, in application
    init_request(request)
  File "/mnt/frappe-axe/apps/frappe/frappe/app.py", line 181, in init_request
    frappe.init(site, sites_path=_sites_path, force=True)
  File "/mnt/frappe-axe/apps/frappe/frappe/__init__.py", line 314, in init
    setup_module_map(include_all_apps=not (frappe.request or frappe.job or frappe.flags.in_migrate))
  File "/mnt/frappe-axe/apps/frappe/frappe/__init__.py", line 1755, in setup_module_map
    for module in get_module_list(app):
                  ^^^^^^^^^^^^^^^^^^^^
  File "/mnt/frappe-axe/apps/frappe/frappe/__init__.py", line 1603, in get_module_list
    return get_file_items(get_app_path(app_name, "modules.txt"))
                          ^^^^^^^^^^^^^^^^^^^^^^^^^^^^^^^^^^^^^
  File "/mnt/frappe-axe/apps/frappe/frappe/__init__.py", line 1568, in get_app_path
    return get_pymodule_path(app_name, *joins)
           ^^^^^^^^^^^^^^^^^^^^^^^^^^^^^^^^^^^
  File "/mnt/frappe-axe/apps/frappe/frappe/__init__.py", line 1598, in get_pymodule_path
    return abspath(join(dirname(get_module(scrub(modulename)).__file__ or ""), *joins))
                                ^^^^^^^^^^^^^^^^^^^^^^^^^^^^^
  File "/mnt/frappe-axe/apps/frappe/frappe/__init__.py", line 1539, in get_module
    return importlib.import_module(modulename)
           ^^^^^^^^^^^^^^^^^^^^^^^^^^^^^^^^^^^
  File "/usr/lib/python3.12/importlib/__init__.py", line 90, in import_module
    return _bootstrap._gcd_import(name[level:], package, level)
           ^^^^^^^^^^^^^^^^^^^^^^^^^^^^^^^^^^^^^^^^^^^^^^^^^^^^
  File "<frozen importlib._bootstrap>", line 1387, in _gcd_import
  File "<frozen importlib._bootstrap>", line 1360, in _find_and_load
  File "<frozen importlib._bootstrap>", line 1324, in _find_and_load_unlocked
ModuleNotFoundError: No module named 'healthcare'

During handling of the above exception, another exception occurred:

Traceback (most recent call last):
  File "/mnt/frappe-axe/apps/frappe/frappe/utils/error.py", line 87, in log_error_snapshot
    log_error(title=str(exception), defer_insert=True)
  File "/mnt/frappe-axe/apps/frappe/frappe/utils/error.py", line 62, in log_error
    error_log = frappe.get_doc(
                ^^^^^^^^^^^^^^^
  File "/mnt/frappe-axe/apps/frappe/frappe/__init__.py", line 1396, in get_doc
    doc = frappe.model.document.get_doc(*args, **kwargs)
          ^^^^^^^^^^^^^^^^^^^^^^^^^^^^^^^^^^^^^^^^^^^^^^
  File "/mnt/frappe-axe/apps/frappe/frappe/model/utils/__init__.py", line 171, in wrapper
    return func(*args, **kw)
           ^^^^^^^^^^^^^^^^^
  File "/mnt/frappe-axe/apps/frappe/frappe/model/document.py", line 69, in get_doc
    return get_doc_from_dict(kwargs)
           ^^^^^^^^^^^^^^^^^^^^^^^^^
  File "/mnt/frappe-axe/apps/frappe/frappe/model/document.py", line 93, in get_doc_from_dict
    controller = get_controller(data["doctype"])
                 ^^^^^^^^^^^^^^^^^^^^^^^^^^^^^^^
  File "/mnt/frappe-axe/apps/frappe/frappe/model/base_document.py", line 67, in get_controller
    return import_controller(doctype)
           ^^^^^^^^^^^^^^^^^^^^^^^^^^
  File "/mnt/frappe-axe/apps/frappe/frappe/model/base_document.py", line 91, in import_controller
    module = load_doctype_module(doctype, module_name)
             ^^^^^^^^^^^^^^^^^^^^^^^^^^^^^^^^^^^^^^^^^
  File "/mnt/frappe-axe/apps/frappe/frappe/modules/utils.py", line 247, in load_doctype_module
    app = get_module_app(module)
          ^^^^^^^^^^^^^^^^^^^^^^
  File "/mnt/frappe-axe/apps/frappe/frappe/modules/utils.py", line 270, in get_module_app
    app = frappe.local.module_app.get(scrub(module))
          ^^^^^^^^^^^^^^^^^^^^^^^^^^^
AttributeError: 'NoneType' object has no attribute 'get'
